Workbook

Sheet Today
B2: Today's Session
B3: Larkfield Instruments · three historical years · about 60 minutes
B4: Do not build the forecast today. Historicals, ratios, assumptions - then stop.
B7: Step | C7: Time | D7: Task | E7: What to do | F7: How to check yourself
B8: 1 | C8: 15 min | D8: Type the historicals into your skeleton | E8: Three years, every line, straight into the columns you already built. All of it in BLUE - these are inputs. Use the Historicals tab here if you would rather not retype from the report. | F8: Check: your balance check row reads zero in all three years. If it does not, the transcription is wrong, not the model.
B9: 2 | C9: 25 min | D9: Compute every historical ratio | E9: Fill in the Ratio Worksheet tab. Each row names the formula so you are practising the calculation, not guessing the definition. Do all three years for every ratio. | F9: Check against the Answer Key tab only AFTER you have filled the whole sheet. Checking row by row turns this into copying.
B10: 3 | C10: 20 min | D10: Set your forecast assumptions | E10: One value per assumption, in blue, in your assumptions block. For each one decide: stable ratio so use the average, drifting so project the trend, or fixed so use inflation. | F10: The Answer Key tab has a defensible answer for each and the reason. Yours can differ - but you should be able to say why.
B13: BEFORE YOU CALL IT DONE - the closing sweep
C15: Balance check reads zero in all three years.
C16: Every number you typed is blue. Every number you calculated is black.
C17: Minimum cash balance is in your assumptions - note 5, $60.0m. You have missed it twice.
C18: Dividends as a % of net income is in your assumptions - note 7, about one third.
C19: There is a Total Liabilities row on the balance sheet.
C20: For every balance sheet line, its change is on the cash flow statement.
C21: For every change on the cash flow statement, there is a balance it came from.

Sheet Historicals
B2: Larkfield Instruments plc
B3: Fictional company. $ millions. Fiscal years ended 30 June.
B4: Every figure below is a hardcoded input - shown in blue, the convention you should be using.
B7: $ millions | D7: FY2022 | E7: FY2023 | F7: FY2024
B8: INCOME STATEMENT
B9: Revenue | D9: 820.4 | E9: 889.6 | F9: 950.2
B10: Cost of sales | D10: -475.8 | E10: -510.6 | F10: -540.7
B11: Gross profit | D11: 344.6 | E11: 379 | F11: 409.5
B12: Selling, general and administrative | D12: -168 | E12: -176.1 | F12: -183
B13: Research and development | D13: -57.4 | E13: -62.3 | F13: -67.5
B14: Depreciation | D14: -34 | E14: -36.5 | F14: -39.2
B15: Operating profit (EBIT) | D15: 85.2 | E15: 104.1 | F15: 119.8
B16: Interest expense | D16: -14.2 | E16: -13.4 | F16: -12.5
B17: Interest income | D17: 0.9 | E17: 1.3 | F17: 2
B18: Profit before tax | D18: 71.9 | E18: 92 | F18: 109.3
B19: Income tax expense | D19: -17.6 | E19: -22.5 | F19: -26.2
B20: Net income | D20: 54.3 | E20: 69.5 | F20: 83.1
B21: Dividends declared | D21: -21.6 | E21: -24.8 | F21: -27.4
B23: BALANCE SHEET
B24: Cash and cash equivalents | D24: 133.6 | E24: 127.4 | F24: 118.3
B25: Trade receivables | D25: 116.9 | E25: 131.6 | F25: 145.8
B26: Inventories | D26: 101.7 | E26: 111.9 | F26: 120
B27: Total current assets | D27: 352.2 | E27: 370.9 | F27: 384.1
B28: Property, plant and equipment, net | D28: 278 | E28: 290.5 | F28: 304.3
B29: Goodwill | D29: 112 | E29: 112 | F29: 112
B30: Intangible assets | D30: 38 | E30: 38 | F30: 38
B31: Total assets | D31: 780.2 | E31: 811.4 | F31: 838.4
B32: Trade payables | D32: 57.4 | E32: 63 | F32: 66.7
B33: Income taxes payable | D33: 2.9 | E33: 3.8 | F33: 4.4
B34: Short-term borrowings | D34: 35 | E34: 35 | F34: 30
B35: Revolving credit facility drawn | D35: 0 | E35: 0 | F35: 0
... B42: Total liabilities and equity | D42: 780.2 | E42: 811.4 | F42: 838.4
B44: CASH FLOW STATEMENT
B45: Net income | D45: 54.3 | E45: 69.5 | F45: 83.1
B46: Depreciation add-back | D46: 34 | E46: 36.5 | F46: 39.2
B47: Change in trade receivables | D47: -10.4 | E47: -14.7 | F47: -14.2
B48: Change in inventories | D48: -7.7 | E48: -10.2 | F48: -8.1
B49: Change in trade payables | D49: 3.7 | E49: 5.6 | F49: 3.7
B50: Change in income taxes payable | D50: 0.6 | E50: 0.9 | F50: 0.6
B51: Net cash from operating activities | D51: 74.5 | E51: 87.6 | F51: 104.3
...

Sheet Ratio Worksheet
B2: Ratio Worksheet
B3: Fill the yellow cells yourself, referencing your own model. Do the whole sheet before you open the Answer Key.
B6: Ratio | C6: How to compute it | D6: FY2022 | E6: FY2023 | F6: FY2024
B7: GROWTH AND MARGIN
B8: Revenue growth % | C8: this year / last year - 1 | D8: n/a
B9: Gross margin % | C9: gross profit / revenue
B10: SG&A as % of revenue | C10: SG&A / revenue (watch this one)
B11: SG&A growth % | C11: this year / last year - 1 (compare to the line above) | D11: n/a
B12: R&D as % of revenue | C12: R&D / revenue
B13: Effective tax rate | C13: tax expense / profit before tax
B14: Dividend payout % | C14: dividends / net income
B16: WORKING CAPITAL DAYS
B17: Days sales outstanding | C17: receivables / revenue x 365
B18: Days inventory held | C18: inventory / COGS x 365 (COGS, not revenue)
B19: Days payables outstanding | C19: payables / COGS x 365
B20: Income tax payable days | C20: tax payable / tax expense x 365
B22: FIXED ASSETS
B23: Capex as % of revenue | C23: capex / revenue
B24: Depreciation as % of opening PP&E | C24: depreciation / OPENING net book value
B26: DEBT
B27: Long-term debt interest rate | C27: interest expense / average long-term debt (will NOT match the note - see why in the key) | D27: n/a

Sheet Answer Key
B2: Answer Key
B3: Every figure here is a live formula reading the Historicals tab - click a cell to see the calculation.
B6: Ratio | C6: How to compute it | D6: FY2022 | E6: FY2023 | F6: FY2024
B7: GROWTH AND MARGIN
B8: Revenue growth % | C8: this year / last year - 1 | D8: n/a | E8: =Historicals!E9/Historicals!D9-1 | F8: =Historicals!F9/Historicals!E9-1
B9: Gross margin % | C9: gross profit / revenue | D9: =Historicals!D11/Historicals!D9 | E9: =Historicals!E11/Historicals!E9 | F9: =Historicals!F11/Historicals!F9
B10: SG&A as % of revenue | C10: SG&A / revenue (watch this one) | D10: =-Historicals!D12/Historicals!D9 | E10: =-Historicals!E12/Historicals!E9 | F10: =-Historicals!F12/Historicals!F9
B11: SG&A growth % | C11: this year / last year - 1 (compare to the line above) | D11: n/a | E11: =Historicals!E12/Historicals!D12-1 | F11: =Historicals!F12/Historicals!E12-1
B12: R&D as % of revenue | C12: R&D / revenue | D12: =-Historicals!D13/Historicals!D9 | E12: =-Historicals!E13/Historicals!E9 | F12: =-Historicals!F13/Historicals!F9
B13: Effective tax rate | C13: tax expense / profit before tax | D13: =-Historicals!D19/Historicals!D18 | E13: =-Historicals!E19/Historicals!E18 | F13: =-Historicals!F19/Historicals!F18
B14: Dividend payout % | C14: dividends / net income | D14: =-Historicals!D21/Historicals!D20 | E14: =-Historicals!E21/Historicals!E20 | F14: =-Historicals!F21/Historicals!F20
B16: WORKING CAPITAL DAYS
B17: Days sales outstanding | C17: receivables / revenue x 365 | D17: =Historicals!D25/Historicals!D9*365 | E17: =Historicals!E25/Historicals!E9*365 | F17: =Historicals!F25/Historicals!F9*365
B18: Days inventory held | C18: inventory / COGS x 365 (COGS, not revenue) | D18: =Historicals!D26/-Historicals!D10*365 | E18: =Historicals!E26/-Historicals!E10*365 | F18: =Historicals!F26/-Historicals!F10*365
B19: Days payables outstanding | C19: payables / COGS x 365 | D19: =Historicals!D32/-Historicals!D10*365 | E19: =Historicals!E32/-Historicals!E10*365 | F19: =Historicals!F32/-Historicals!F10*365
B20: Income tax payable days | C20: tax payable / tax expense x 365 | D20: =Historicals!D33/-Historicals!D19*365 | E20: =Historicals!E33/-Historicals!E19*365 | F20: =Historicals!F33/-Historicals!F19*365
B22: FIXED ASSETS
B23: Capex as % of revenue | C23: capex / revenue | D23: =-Historicals!D52/Historicals!D9 | E23: =-Historicals!E52/Historicals!E9 | F23: =-Historicals!F52/Historicals!F9
B24: Depreciation as % of opening PP&E | C24: depreciation / OPENING net book value | D24: =-Historicals!D14/Historicals!D64 | E24: =-Historicals!E14/Historicals!E64 | F24: =-Historicals!F14/Historicals!F64
B26: DEBT
B27: Long-term debt interest rate | C27: interest expense / average long-term debt (will NOT match the note - see why in the key) | D27: n/a | E27: =-Historicals!E16/AVERAGE(Historicals!E37,Historicals!D37) | F27: =-Historicals!F16/AVERAGE(Historicals!F37,Historicals!E37)
B30: WHAT TO SET EACH ASSUMPTION TO
B31: Yours can differ from these - but you should be able to say why.
B33: Assumption | C33: Set it to | D33: Because
B34: Revenue growth % | C34: 6.0% to 6.5% | D34: Growth decelerated 8.4% to 6.8%. Note 1 guides to mid-single digits. Take the trend, not the average.
B35: Gross margin % | C35: 43.1%, or creep to 43.5% | D35: Rising steadily 42.0 / 42.6 / 43.1. A drifting ratio - project the trend, do not average it back down.
B36: SG&A | C36: Grow at inflation, about 4% | D36: THE TRAP. As a % of revenue it FALLS 20.5 / 19.8 / 19.3, which looks like a trend but is not one - it is a fixed cost being divided by a growing number. Its own growth is a steady ~4.5%. Note 2 says substantially fixed.
B37: R&D as % of revenue | C37: 7.0% | D37: Dead stable at 7.0 / 7.0 / 7.1. The textbook case for using the average.
B38: Depreciation % of opening PP&E | C38: 13.3% | D38: 12.7 / 13.1 / 13.5 - mild drift up. Anywhere in that range is defensible.
B39: Capex as % of revenue | C39: 5.6% | D39: 5.4 / 5.5 / 5.6. Stable and slightly rising.
B40: Days sales outstanding | C40: 54 to 56 | D40: Lengthening 52 / 54 / 56. Note 3 says management targets below 52 - decide whether you believe them and say so.
B41: Days inventory held | C41: 81 | D41: 78 / 80 / 81, and note 3 flags a build ahead of an FY2025 product transition.
B42: Days payables outstanding | C42: 45 | D42: 44 / 45 / 45. Flat.
B43: Income tax payable days | C43: 61 | D43: 60 / 62 / 61. Flat - use the average.
B44: Effective tax rate | C44: 24.0% | D44: 24.5 / 24.5 / 24.0. Note 6 attributes the fall to profit mix, so carry the latest.
... B55: Inflation rate | C55: 4.0% | D55: Implied by SG&A growth of about 4.5% and used for the fixed cost lines.
